Workbook

Sheet README
A1: Indian Criminal Law Dataset (BNS 2023)
A3: Purpose | B3: Question/explanation records on sections of the Bharatiya Nyaya Sanhita (BNS) 2023, for lookup and analysis.
A4: Records | B4: =COUNTA(Dataset!A2:A5001) -> 5000
A5: Sections covered | B5: =COUNTA(Section_Master!A2:A477) -> 476
A6: Sections with punishment info (incl. N/A) | B6: =COUNTIF(Section_Master!D2:D477,"?*") -> 476
A7: Sections verified (Yes) | B7: =COUNTIF(Section_Master!I2:I477,"Yes") -> 0
A8: Offence sections still blank (to fill) | B8: =COUNTA(Section_Master!A2:A477)-COUNTIF(Section_Master!D2:D477,"?*") -> 0
A9: HOW TO FILL IN
A10: 1 | B10: Open the Section_Master sheet. Yellow cells are the ones you type in. One row per section.
A11: 2 | B11: Fill Punishment, Cognizable, Bailable, Compoundable and Old_IPC_Section from official sources (BNS text, BNSS 2023 First Schedule, MHA/PRS IPC-BNS comparison tables).
A12: 3 | B12: The Dataset sheet picks these values up automatically for every record of that section (columns F to I are formulas - do not type over them).
A13: 4 | B13: Set Verified to Yes only after you have checked the row against the official source, and paste the link in Official_Source.
A15: COLUMN GUIDE (Dataset)
A16: case_ID | B16: Unique record number.
A17: Law_name | B17: Law the record belongs to (currently only BNS).
A18: Offence_name | B18: Section heading / topic as given in the source records.
A19: Case_Description | B19: Explanation or answer text about the section (not an actual court case).
A20: BNS_section | B20: Section number (now stored as a number).
A21: Punishment, Cognizable, Bailable, Compoundable | B21: Filled automatically from Section_Master.
A22: Category | B22: Record type: definitional_topic, definitional_section, scenario, elements, exceptions, consequence.
A23: Source | B23: Origin of the record.
A25: NOTES AND LIMITATIONS
A26: Source | B26: All records are tagged "Hugging Face source record". If this dataset is part of a graded project, cite that source clearly and check its licence, or replace the text with your own wording.
A27: Disclaimer | B27: Educational dataset. Not legal advice. Verify against the official Act before relying on it.
A28: Law_name correction | B28: Sections 359 to 476 are procedural provisions of the BNSS 2023 (appeals, compounding, execution of sentences), not the BNS, which ends at section 358. Law_name for those 118 records was changed from BNS to BNSS.

Sheet Dataset
A1: case_ID | B1: Law_name | C1: Offence_name | D1: Case_Description | E1: BNS_section | F1: Punishment | G1: Cognizable | H1: Bailable | I1: Compoundable | J1: Category | K1: Source
A2: CASE_0001 | B2: BNS | C2: Short title, commencement and application | D2: Any person liable under Indian law to be tried for an offence committed beyond India will be dealt with as if the act was committed within India. The law also applies to any citizen of India outside the country, any person on an Indian-registered ship or aircraft, and anyone committing an offence targeting an Indian computer resource from outside India. [Source: Section 1, BNS 2023] | E2: 1 | F2: =IFERROR(INDEX(Section_Master!$D$2:$D$477,MATCH($E2,Section_Master!$A$2:$A$477,0))&"","") -> Not applicable - no offence or penalty defined here (definition, exception or general provision) | G2: =IFERROR(INDEX(Section_Master!$E$2:$E$477,MATCH($E2,Section_Master!$A$2:$A$477,0))&"","") -> N/A | H2: =IFERROR(INDEX(Section_Master!$F$2:$F$477,MATCH($E2,Section_Master!$A$2:$A$477,0))&"","") -> N/A | I2: =IFERROR(INDEX(Section_Master!$G$2:$G$477,MATCH($E2,Section_Master!$A$2:$A$477,0))&"","") -> N/A | J2: definitional_topic | K2: Hugging Face source record: BNS_1
A3: CASE_0002 | B3: BNS | C3: Short title, commencement and application | D3: Section 1 of BNS 2023 establishes the title, commencement date, and jurisdictional application of the Act. It states that every person in India is subject to this code, and extends its reach to Indian citizens globally, people on Indian-registered ships or aircraft, and individuals abroad targeting Indian computer resources. [Source: Section 1, BNS 2023] | E3: 1 | F3: =IFERROR(INDEX(Section_Master!$D$2:$D$477,MATCH($E3,Section_Master!$A$2:$A$477,0))&"","") -> Not applicable - no offence or penalty defined here (definition, exception or general provision) | G3: =IFERROR(INDEX(Section_Master!$E$2:$E$477,MATCH($E3,Section_Master!$A$2:$A$477,0))&"","") -> N/A | H3: =IFERROR(INDEX(Section_Master!$F$2:$F$477,MATCH($E3,Section_Master!$A$2:$A$477,0))&"","") -> N/A | I3: =IFERROR(INDEX(Section_Master!$G$2:$G$477,MATCH($E3,Section_Master!$A$2:$A$477,0))&"","") -> N/A | J3: definitional_section | K3: Hugging Face source record: BNS_1
A4: CASE_0003 | B4: BNS | C4: Short title, commencement and application | D4: Yes. If an Indian citizen commits a murder in any place outside and beyond India, they can be tried and convicted of murder in any place in India where they may be found. [Source: Section 1, BNS 2023] | E4: 1 | F4: =IFERROR(INDEX(Section_Master!$D$2:$D$477,MATCH($E4,Section_Master!$A$2:$A$477,0))&"","") -> Not applicable - no offence or penalty defined here (definition, exception or general provision) | G4: =IFERROR(INDEX(Section_Master!$E$2:$E$477,MATCH($E4,Section_Master!$A$2:$A$477,0))&"","") -> N/A | H4: =IFERROR(INDEX(Section_Master!$F$2:$F$477,MATCH($E4,Section_Master!$A$2:$A$477,0))&"","") -> N/A | I4: =IFERROR(INDEX(Section_Master!$G$2:$G$477,MATCH($E4,Section_Master!$A$2:$A$477,0))&"","") -> N/A | J4: scenario | K4: Hugging Face source record: BNS_1
A5: CASE_0004 | B5: BNS | C5: Short title, commencement and application | D5: A person in a place outside and beyond India can be prosecuted under Indian law if they commit an offence that targets a computer resource located in India. [Source: Section 1, BNS 2023] | E5: 1 | F5: =IFERROR(INDEX(Section_Master!$D$2:$D$477,MATCH($E5,Section_Master!$A$2:$A$477,0))&"","") -> Not applicable - no offence or penalty defined here (definition, exception or general provision) | G5: =IFERROR(INDEX(Section_Master!$E$2:$E$477,MATCH($E5,Section_Master!$A$2:$A$477,0))&"","") -> N/A | H5: =IFERROR(INDEX(Section_Master!$F$2:$F$477,MATCH($E5,Section_Master!$A$2:$A$477,0))&"","") -> N/A | I5: =IFERROR(INDEX(Section_Master!$G$2:$G$477,MATCH($E5,Section_Master!$A$2:$A$477,0))&"","") -> N/A | J5: elements | K5: Hugging Face source record: BNS_1
A6: CASE_0005 | B6: BNS | C6: Short title, commencement and application | D6: Yes, nothing in the Bharatiya Nyaya Sanhita affects the provisions of any Act punishing mutiny and desertion of officers, soldiers, sailors, or airmen in the service of the Government of India, nor does it affect any special or local law. [Source: Section 1, BNS 2023] | E6: 1 | F6: =IFERROR(INDEX(Section_Master!$D$2:$D$477,MATCH($E6,Section_Master!$A$2:$A$477,0))&"","") -> Not applicable - no offence or penalty defined here (definition, exception or general provision) | G6: =IFERROR(INDEX(Section_Master!$E$2:$E$477,MATCH($E6,Section_Master!$A$2:$A$477,0))&"","") -> N/A | H6: =IFERROR(INDEX(Section_Master!$F$2:$F$477,MATCH($E6,Section_Master!$A$2:$A$477,0))&"","") -> N/A | I6: =IFERROR(INDEX(Section_Master!$G$2:$G$477,MATCH($E6,Section_Master!$A$2:$A$477,0))&"","") -> N/A | J6: exceptions | K6: Hugging Face source record: BNS_1
A7: CASE_0006 | B7: BNS | C7: Short title, commencement and application | D7: The act committed outside India is treated in the exact same manner as if such act had been committed within India, making the person liable to be dealt with according to the provisions of this code. [Source: Section 1, BNS 2023] | E7: 1 | F7: =IFERROR(INDEX(Section_Master!$D$2:$D$477,MATCH($E7,Section_Master!$A$2:$A$477,0))&"","") -> Not applicable - no offence or penalty defined here (definition, exception or general provision) | G7: =IFERROR(INDEX(Section_Master!$E$2:$E$477,MATCH($E7,Section_Master!$A$2:$A$477,0))&"","") -> N/A | H7: =IFERROR(INDEX(Section_Master!$F$2:$F$477,MATCH($E7,Section_Master!$A$2:$A$477,0))&"","") -> N/A | I7: =IFERROR(INDEX(Section_Master!$G$2:$G$477,MATCH($E7,Section_Master!$A$2:$A$477,0))&"","") -> N/A | J7: consequence | K7: Hugging Face source record: BNS_1
A8: CASE_0007 | B8: BNS | C8: Definitions | D8: The definitions section provides specific meanings for various terms used throughout the Act to ensure consistent interpretation. These definitions apply unless the context requires otherwise. [Source: Section 2, BNS 2023] | E8: 2 | F8: =IFERROR(INDEX(Section_Master!$D$2:$D$477,MATCH($E8,Section_Master!$A$2:$A$477,0))&"","") -> Not applicable - no offence or penalty defined here (definition, exception or general provision) | G8: =IFERROR(INDEX(Section_Master!$E$2:$E$477,MATCH($E8,Section_Master!$A$2:$A$477,0))&"","") -> N/A | H8: =IFERROR(INDEX(Section_Master!$F$2:$F$477,MATCH($E8,Section_Master!$A$2:$A$477,0))&"","") -> N/A | I8: =IFERROR(INDEX(Section_Master!$G$2:$G$477,MATCH($E8,Section_Master!$A$2:$A$477,0))&"","") -> N/A | J8: definitional_topic | K8: Hugging Face source record: BNS_2
A9: CASE_0008 | B9: BNS | C9: Definitions | D9: Section 2 of BNS 2023 contains the definitions of key terms used throughout the Sanhita. It establishes the legal meaning of specific words to ensure uniform understanding across all subsequent provisions. [Source: Section 2, BNS 2023] | E9: 2 | F9: =IFERROR(INDEX(Section_Master!$D$2:$D$477,MATCH($E9,Section_Master!$A$2:$A$477,0))&"","") -> Not applicable - no offence or penalty defined here (definition, exception or general provision) | G9: =IFERROR(INDEX(Section_Master!$E$2:$E$477,MATCH($E9,Section_Master!$A$2:$A$477,0))&"","") -> N/A | H9: =IFERROR(INDEX(Section_Master!$F$2:$F$477,MATCH($E9,Section_Master!$A$2:$A$477,0))&"","") -> N/A | I9: =IFERROR(INDEX(Section_Master!$G$2:$G$477,MATCH($E9,Section_Master!$A$2:$A$477,0))&"","") -> N/A | J9: definitional_section | K9: Hugging Face source record: BNS_2
A10: CASE_0009 | B10: BNS | C10: Definitions | D10: The terms defined in this section carry their specified meanings throughout the Act unless a contrary intention appears from the specific context in which they are used later. [Source: Section 2, BNS 2023] | E10: 2 | F10: =IFERROR(INDEX(Section_Master!$D$2:$D$477,MATCH($E10,Section_Master!$A$2:$A$477,0))&"","") -> Not applicable - no offence or penalty defined here (definition, exception or general provision) | G10: =IFERROR(INDEX(Section_Master!$E$2:$E$477,MATCH($E10,Section_Master!$A$2:$A$477,0))&"","") -> N/A | H10: =IFERROR(INDEX(Section_Master!$F$2:$F$477,MATCH($E10,Section_Master!$A$2:$A$477,0))&"","") -> N/A | I10: =IFERROR(INDEX(Section_Master!$G$2:$G$477,MATCH($E10,Section_Master!$A$2:$A$477,0))&"","") -> N/A | J10: scenario | K10: Hugging Face source record: BNS_2
A11: CASE_0010 | B11: BNS | C11: Definitions | D11: The definition applies universally across the Act, provided that the context of the specific provision does not indicate a contrary intention. [Source: Section 2, BNS 2023] | E11: 2 | F11: =IFERROR(INDEX(Section_Master!$D$2:$D$477,MATCH($E11,Section_Master!$A$2:$A$477,0))&"","") -> Not applicable - no offence or penalty defined here (definition, exception or general provision) | G11: =IFERROR(INDEX(Section_Master!$E$2:$E$477,MATCH($E11,Section_Master!$A$2:$A$477,0))&"","") -> N/A | H11: =IFERROR(INDEX(Section_Master!$F$2:$F$477,MATCH($E11,Section_Master!$A$2:$A$477,0))&"","") -> N/A | I11: =IFERROR(INDEX(Section_Master!$G$2:$G$477,MATCH($E11,Section_Master!$A$2:$A$477,0))&"","") -> N/A | J11: elements | K11: Hugging Face source record: BNS_2
A12: CASE_0011 | B12: BNS | C12: Definitions | D12: Yes, the definitions apply generally, but they are limited by any contrary intention that may appear from the context of a specific provision where the term is used. [Source: Section 2, BNS 2023] | E12: 2 | F12: =IFERROR(INDEX(Section_Master!$D$2:$D$477,MATCH($E12,Section_Master!$A$2:$A$477,0))&"","") -> Not applicable - no offence or penalty defined here (definition, exception or general provision) | G12: =IFERROR(INDEX(Section_Master!$E$2:$E$477,MATCH($E12,Section_Master!$A$2:$A$477,0))&"","") -> N/A | H12: =IFERROR(INDEX(Section_Master!$F$2:$F$477,MATCH($E12,Section_Master!$A$2:$A$477,0))&"","") -> N/A | I12: =IFERROR(INDEX(Section_Master!$G$2:$G$477,MATCH($E12,Section_Master!$A$2:$A$477,0))&"","") -> N/A | J12: exceptions | K12: Hugging Face source record: BNS_2
A13: CASE_0012 | B13: BNS | C13: Definitions | D13: The legal consequence is that the defined word must be interpreted strictly according to its provided meaning everywhere it appears in the Act, overriding general dictionary definitions, unless context dictates otherwise. [Source: Section 2, BNS 2023] | E13: 2 | F13: =IFERROR(INDEX(Section_Master!$D$2:$D$477,MATCH($E13,Section_Master!$A$2:$A$477,0))&"","") -> Not applicable - no offence or penalty defined here (definition, exception or general provision) | G13: =IFERROR(INDEX(Section_Master!$E$2:$E$477,MATCH($E13,Section_Master!$A$2:$A$477,0))&"","") -> N/A | H13: =IFERROR(INDEX(Section_Master!$F$2:$F$477,MATCH($E13,Section_Master!$A$2:$A$477,0))&"","") -> N/A | I13: =IFERROR(INDEX(Section_Master!$G$2:$G$477,MATCH($E13,Section_Master!$A$2:$A$477,0))&"","") -> N/A | J13: consequence | K13: Hugging Face source record: BNS_2
... A5001: CASE_5000 | B5001: BNSS | C5001: Concurrent power of Central Government in case of death sentences | D5001: Section 476 of BNSS 2023 establishes the "Concurrent power of Central Government in case of death sentences," granting the Central Government the same powers to suspend, remit, or commute death sentences (under sections 473 and 474) as are conferred upon the State Government. [Source: Section 476, BNSS 2023] | E5001: 476 | F5001: =IFERROR(INDEX(Section_Master!$D$2:$D$477,MATCH($E5001,Section_Master!$A$2:$A$477,0))&"","") -> Not applicable - procedural provision (BNSS), no offence defined | G5001: =IFERROR(INDEX(Section_Master!$E$2:$E$477,MATCH($E5001,Section_Master!$A$2:$A$477,0))&"","") -> N/A | H5001: =IFERROR(INDEX(Section_Master!$F$2:$F$477,MATCH($E5001,Section_Master!$A$2:$A$477,0))&"","") -> N/A | I5001: =IFERROR(INDEX(Section_Master!$G$2:$G$477,MATCH($E5001,Section_Master!$A$2:$A$477,0))&"","") -> N/A | J5001: definitional_section | K5001: Hugging Face source record: BNSS_476

Sheet Section_Master
A1: Section_No | B1: Section_Title | C1: Records | D1: Punishment | E1: Cognizable | F1: Bailable | G1: Compoundable | H1: Old_IPC_Section | I1: Verified | J1: Official_Source
A2: 1 | B2: Short title, commencement and application | C2: =COUNTIF(Dataset!$E$2:$E$5001,A2) -> 12 | D2: Not applicable - no offence or penalty defined here (definition, exception or general provision) | E2: N/A | F2: N/A | G2: N/A | J2: BNS 2023 text - confirm no penalty clause
A3: 2 | B3: Definitions | C3: =COUNTIF(Dataset!$E$2:$E$5001,A3) -> 12 | D3: Not applicable - no offence or penalty defined here (definition, exception or general provision) | E3: N/A | F3: N/A | G3: N/A | J3: BNS 2023 text - confirm no penalty clause
A4: 3 | B4: General explanations | C4: =COUNTIF(Dataset!$E$2:$E$5001,A4) -> 12 | D4: Not applicable - no offence or penalty defined here (definition, exception or general provision) | E4: N/A | F4: N/A | G4: N/A | J4: BNS 2023 text - confirm no penalty clause
A5: 4 | B5: Punishments | C5: =COUNTIF(Dataset!$E$2:$E$5001,A5) -> 12 | D5: Not applicable - no offence or penalty defined here (definition, exception or general provision) | E5: N/A | F5: N/A | G5: N/A | J5: BNS 2023 text - confirm no penalty clause
A6: 5 | B6: Commutation of sentence | C6: =COUNTIF(Dataset!$E$2:$E$5001,A6) -> 12 | D6: Not applicable - no offence or penalty defined here (definition, exception or general provision) | E6: N/A | F6: N/A | G6: N/A | J6: BNS 2023 text - confirm no penalty clause
A7: 6 | B7: Fractions of terms of punishment | C7: =COUNTIF(Dataset!$E$2:$E$5001,A7) -> 12 | D7: Not applicable - no offence or penalty defined here (definition, exception or general provision) | E7: N/A | F7: N/A | G7: N/A | J7: BNS 2023 text - confirm no penalty clause
A8: 7 | B8: Sentence may be (in certain cases of imprisonment) wholly or partly rigorous or simple | C8: =COUNTIF(Dataset!$E$2:$E$5001,A8) -> 12 | D8: Not applicable - no offence or penalty defined here (definition, exception or general provision) | E8: N/A | F8: N/A | G8: N/A | J8: BNS 2023 text - confirm no penalty clause
A9: 8 | B9: Amount of fine, liability in default of payment of fine, etc | C9: =COUNTIF(Dataset!$E$2:$E$5001,A9) -> 12 | D9: Not applicable - no offence or penalty defined here (definition, exception or general provision) | E9: N/A | F9: N/A | G9: N/A | J9: BNS 2023 text - confirm no penalty clause
A10: 9 | B10: Limit of punishment of offence made up of several offences | C10: =COUNTIF(Dataset!$E$2:$E$5001,A10) -> 12 | D10: Not applicable - no offence or penalty defined here (definition, exception or general provision) | E10: N/A | F10: N/A | G10: N/A | J10: BNS 2023 text - confirm no penalty clause
A11: 10 | B11: Punishment of person guilty of one of several offences, judgment stating that it is doubtful | C11: =COUNTIF(Dataset!$E$2:$E$5001,A11) -> 12 | D11: Not applicable - no offence or penalty defined here (definition, exception or general provision) | E11: N/A | F11: N/A | G11: N/A | J11: BNS 2023 text - confirm no penalty clause
A12: 11 | B12: Solitary confinement | C12: =COUNTIF(Dataset!$E$2:$E$5001,A12) -> 12 | D12: Not applicable - no offence or penalty defined here (definition, exception or general provision) | E12: N/A | F12: N/A | G12: N/A | J12: BNS 2023 text - confirm no penalty clause
A13: 12 | B13: Limit of solitary confinement | C13: =COUNTIF(Dataset!$E$2:$E$5001,A13) -> 12 | D13: Not applicable - no offence or penalty defined here (definition, exception or general provision) | E13: N/A | F13: N/A | G13: N/A | J13: BNS 2023 text - confirm no penalty clause
... A47: 46 | B47: Abettor | C47: =COUNTIF(Dataset!$E$2:$E$5001,A47) -> 12 | D47: Not applicable - no offence or penalty defined here (definition, exception or general provision) | E47: N/A | F47: N/A | G47: N/A | J47: BNS 2023 text - confirm no penalty clause
A48: 47 | B48: Abetment in India of offences outside India | C48: =COUNTIF(Dataset!$E$2:$E$5001,A48) -> 12 | D48: Punished as for abetting that offence if it were committed in India | E48: Same as underlying offence | F48: Same as underlying offence | G48: Same as underlying offence | H48: 108A | J48: Filled from general knowledge, NOT checked: verify against BNS 2023 text and BNSS 2023 First Schedule
A49: 48 | B49: Abetment outside India for offence in India | C49: =COUNTIF(Dataset!$E$2:$E$5001,A49) -> 12 | D49: Punished as for abetting the offence committed in India | E49: Same as underlying offence | F49: Same as underlying offence | G49: Same as underlying offence | H49: New provision | J49: Filled from general knowledge, NOT checked: verify against BNS 2023 text and BNSS 2023 First Schedule
A50: 49 | B50: Punishment of abetment if act abetted is committed in consequence and where no express provision is made for its punishment | C50: =COUNTIF(Dataset!$E$2:$E$5001,A50) -> 12 | D50: Punishment provided for the offence abetted [s.49] | E50: Same as underlying offence | F50: Same as underlying offence | G50: Same as underlying offence | H50: 109 | J50: Filled from general knowledge, NOT checked: verify against BNS 2023 text and BNSS 2023 First Schedule
A51: 50 | B51: Punishment of abetment if person abetted does act with different intention from that of abettor | C51: =COUNTIF(Dataset!$E$2:$E$5001,A51) -> 12 | D51: Punishment provided for the offence abetted, where the abetted person acts with a different intention [s.50] | E51: Same as underlying offence | F51: Same as underlying offence | G51: Same as underlying offence | H51: 110 | J51: Filled from general knowledge, NOT checked: verify against BNS 2023 text and BNSS 2023 First Schedule
A52: 51 | B52: Liability of abettor when one act abetted and different act done | C52: =COUNTIF(Dataset!$E$2:$E$5001,A52) -> 12 | D52: Abettor liable as if he had abetted the act actually done (liability provision) [s.51] | E52: Same as underlying offence | F52: Same as underlying offence | G52: Same as underlying offence | H52: 111 | J52: Filled from general knowledge, NOT checked: verify against BNS 2023 text and BNSS 2023 First Schedule
A53: 52 | B53: Abettor when liable to cumulative punishment for act abetted and for act done | C53: =COUNTIF(Dataset!$E$2:$E$5001,A53) -> 12 | D53: Abettor liable to cumulative punishment for the act abetted and the act done [s.52] | E53: Same as underlying offence | F53: Same as underlying offence | G53: Same as underlying offence | H53: 112 | J53: Filled from general knowledge, NOT checked: verify against BNS 2023 text and BNSS 2023 First Schedule
A54: 53 | B54: Liability of abettor for an effect caused by act abetted different from that intended by abettor | C54: =COUNTIF(Dataset!$E$2:$E$5001,A54) -> 12 | D54: Abettor liable for the effect caused, as if he had directly abetted it [s.53] | E54: Same as underlying offence | F54: Same as underlying offence | G54: Same as underlying offence | H54: 113 | J54: Filled from general knowledge, NOT checked: verify against BNS 2023 text and BNSS 2023 First Schedule
A55: 54 | B55: Abettor present when offence is committed | C55: =COUNTIF(Dataset!$E$2:$E$5001,A55) -> 12 | D55: Abettor present at the offence is deemed to have committed it, and is punished as for that offence [s.54] | E55: Same as underlying offence | F55: Same as underlying offence | G55: Same as underlying offence | H55: 114 | J55: Filled from general knowledge, NOT checked: verify against BNS 2023 text and BNSS 2023 First Schedule
A56: 55 | B56: Abetment of offence punishable with death or imprisonment for life | C56: =COUNTIF(Dataset!$E$2:$E$5001,A56) -> 12 | D56: Imprisonment up to 7 years and fine; up to 14 years and fine if the act abetted causes harm [s.55] | E56: Same as underlying offence | F56: Same as underlying offence | G56: Same as underlying offence | H56: 115 | J56: Filled from general knowledge, NOT checked: verify against BNS 2023 text and BNSS 2023 First Schedule
A57: 56 | B57: Abetment of offence punishable with imprisonment | C57: =COUNTIF(Dataset!$E$2:$E$5001,A57) -> 12 | D57: Imprisonment up to one-fourth of the longest term for the offence, or fine, or both; up to half of it if the act abetted causes harm [s.56] | E57: Same as underlying offence | F57: Same as underlying offence | G57: Same as underlying offence | H57: 116 | J57: Filled from general knowledge, NOT checked: verify against BNS 2023 text and BNSS 2023 First Schedule
A58: 57 | B58: Abetting commission of offence by public or by more than ten persons | C58: =COUNTIF(Dataset!$E$2:$E$5001,A58) -> 12 | D58: Imprisonment up to 3 years, or fine, or both [s.57] | E58: Same as underlying offence | F58: Same as underlying offence | G58: Same as underlying offence | H58: 117 | J58: Filled from general knowledge, NOT checked: verify against BNS 2023 text and BNSS 2023 First Schedule
A59: 58 | B59: Concealing design to commit offence punishable with death or imprisonment for life | C59: =COUNTIF(Dataset!$E$2:$E$5001,A59) -> 12 | D59: Imprisonment up to 7 years and fine if the offence is committed; up to 3 years and fine if not [s.58] | E59: Same as underlying offence | F59: Same as underlying offence | G59: Same as underlying offence | H59: 118 | J59: Filled from general knowledge, NOT checked: verify against BNS 2023 text and BNSS 2023 First Schedule
... A63: 62 | B63: Punishment for attempting to commit offences punishable with imprisonment for life or other imprisonment | C63: =COUNTIF(Dataset!$E$2:$E$5001,A63) -> 12 | D63: Imprisonment up to half of the longest term for the offence attempted, or fine, or both [s.62] | E63: Same as underlying offence | F63: Same as underlying offence | G63: Same as underlying offence | H63: 511 | J63: Filled from general knowledge, NOT checked: verify against BNS 2023 text and BNSS 2023 First Schedule
A64: 63 | B64: Rape | C64: =COUNTIF(Dataset!$E$2:$E$5001,A64) -> 12 | D64: Not applicable - no offence or penalty defined here (definition, exception or general provision) | E64: N/A | F64: N/A | G64: N/A | J64: BNS 2023 text - confirm no penalty clause
A65: 64 | B65: Punishment for rape | C65: =COUNTIF(Dataset!$E$2:$E$5001,A65) -> 12 | D65: Rigorous imprisonment not less than 10 years, may extend to life, and fine [s.64(1)] | E65: Yes | F65: No | G65: No | H65: 376 | J65: Filled from general knowledge, NOT checked: verify against BNS 2023 text and BNSS 2023 First Schedule
A66: 65 | B66: Punishment for rape in certain cases | C66: =COUNTIF(Dataset!$E$2:$E$5001,A66) -> 12 | D66: Rigorous imprisonment not less than 20 years, may extend to life (remainder of natural life), and fine; death if victim is under 12 [s.65] | E66: Yes | F66: No | G66: No | H66: 376(3), 376AB | J66: Filled from general knowledge, NOT checked: verify against BNS 2023 text and BNSS 2023 First Schedule
A67: 66 | B67: Punishment for causing death or resulting in persistent vegetative state of victim | C67: =COUNTIF(Dataset!$E$2:$E$5001,A67) -> 12 | D67: Rigorous imprisonment not less than 20 years, may extend to life (remainder of natural life), or death | E67: Yes | F67: No | G67: No | H67: 376A | J67: Filled from general knowledge, NOT checked: verify against BNS 2023 text and BNSS 2023 First Schedule
A68: 67 | B68: Sexual intercourse by husband upon his wife during separation | C68: =COUNTIF(Dataset!$E$2:$E$5001,A68) -> 12 | D68: Rigorous imprisonment not less than 2 years, may extend to 7 years, and fine | E68: Yes | F68: No | G68: No | H68: 376B | J68: Filled from general knowledge, NOT checked: verify against BNS 2023 text and BNSS 2023 First Schedule
A69: 68 | B69: Sexual intercourse by a person in authority | C69: =COUNTIF(Dataset!$E$2:$E$5001,A69) -> 12 | D69: Rigorous imprisonment not less than 5 years, may extend to 10 years, and fine | E69: Yes | F69: No | G69: No | H69: 376C | J69: Filled from general knowledge, NOT checked: verify against BNS 2023 text and BNSS 2023 First Schedule
A70: 69 | B70: Sexual intercourse by employing deceitful means, etc | C70: =COUNTIF(Dataset!$E$2:$E$5001,A70) -> 12 | D70: Imprisonment up to 10 years and fine | E70: Yes | F70: No | G70: No | H70: New provision | J70: Filled from general knowledge, NOT checked: verify against BNS 2023 text and BNSS 2023 First Schedule
A71: 70 | B71: Gang rape | C71: =COUNTIF(Dataset!$E$2:$E$5001,A71) -> 12 | D71: Rigorous imprisonment not less than 20 years, may extend to life (remainder of natural life), and fine; life or death if victim is under 18 [s.70] | E71: Yes | F71: No | G71: No | H71: 376D, 376DA, 376DB | J71: Filled from general knowledge, NOT checked: verify against BNS 2023 text and BNSS 2023 First Schedule
A72: 71 | B72: Punishment for repeat offenders | C72: =COUNTIF(Dataset!$E$2:$E$5001,A72) -> 12 | D72: Imprisonment for life (remainder of natural life), or death | E72: Yes | F72: No | G72: No | H72: 376E | J72: Filled from general knowledge, NOT checked: verify against BNS 2023 text and BNSS 2023 First Schedule
A73: 72 | B73: Disclosure of identity of victim of certain offences, etc | C73: =COUNTIF(Dataset!$E$2:$E$5001,A73) -> 12 | D73: Imprisonment up to 2 years and fine | E73: Yes | F73: Yes | G73: No | H73: 228A(1)-(2) | J73: Filled from general knowledge, NOT checked: verify against BNS 2023 text and BNSS 2023 First Schedule
A74: 73 | B74: Printing or publishing any matter relating to Court proceedings without permission | C74: =COUNTIF(Dataset!$E$2:$E$5001,A74) -> 12 | D74: Imprisonment up to 2 years and fine | E74: Yes | F74: Yes | G74: No | H74: 228A(3) | J74: Filled from general knowledge, NOT checked: verify against BNS 2023 text and BNSS 2023 First Schedule
A75: 74 | B75: Assault or use of criminal force to woman with intent to outrage her modesty | C75: =COUNTIF(Dataset!$E$2:$E$5001,A75) -> 12 | D75: Imprisonment not less than 1 year, may extend to 5 years, and fine | E75: Yes | F75: No | G75: No | H75: 354 | J75: Filled from general knowledge, NOT checked: verify against BNS 2023 text and BNSS 2023 First Schedule
A76: 75 | B76: Sexual harassment | C76: =COUNTIF(Dataset!$E$2:$E$5001,A76) -> 12 | D76: Rigorous imprisonment up to 3 years, or fine, or both [s.75(2)]; up to 1 year, or fine, or both for sexually coloured remarks [s.75(3)] | E76: Yes | F76: Yes | G76: No | H76: 354A | J76: Filled from general knowledge, NOT checked: verify against BNS 2023 text and BNSS 2023 First Schedule
...
